Workbook
Name start_age: Inputs!$B$5
Name cycles: Inputs!$B$6
Name incidence_rate: Inputs!$B$7
Name rrr_intervention: Inputs!$B$8
Name cost_intervention_annual: Inputs!$B$9
Name cost_disease_annual: Inputs!$B$10
Name cost_well_annual: Inputs!$B$11
Name utility_well: Inputs!$B$12
Name utility_disease: Inputs!$B$13
Name excess_mortality_rate: Inputs!$B$14
Name discount_rate: Inputs!$B$15
Name wtp: Inputs!$B$16
Name gompertz_a: Inputs!$B$17
Name gompertz_b: Inputs!$B$18
Name cycle_length: Inputs!$B$19
Name half_cycle: Inputs!$B$20

Sheet Results
A1: Incremental cost-effectiveness
A2: Genomic-guided vs standard care. Every cell below is a formula over the two trace sheets; change any input and this moves.
A4: Standard care - total cost | B4: ='Trace_SC'!R50 | C4: Discounted, half-cycle corrected
A5: Standard care - total QALYs | B5: ='Trace_SC'!S50
A6: Standard care - life years | B6: ='Trace_SC'!T50
A7: Genomic-guided - total cost | B7: ='Trace_GG'!R50 | C7: Includes the annual intervention cost while Well
A8: Genomic-guided - total QALYs | B8: ='Trace_GG'!S50
A9: Genomic-guided - life years | B9: ='Trace_GG'!T50
A10: Incremental cost (dC) | B10: ='Trace_GG'!R50-'Trace_SC'!R50 | C10: Guided minus standard care
A11: Incremental QALYs (dQ) | B11: ='Trace_GG'!S50-'Trace_SC'!S50
A12: Incremental life years | B12: ='Trace_GG'!T50-'Trace_SC'!T50
A14: Dominant (cheaper AND more effective) | B14: =IF(AND(B10<0,B11>0),"YES","no")
A15: Dominated (costlier AND less effective) | B15: =IF(AND(B10>0,B11<0),"YES","no")
A16: ICER ($/QALY) | B16: =IF(OR(B14="YES",B15="YES"),"suppressed (dominance)",IF(ABS(B11)<1E-09,"undefined",B10/B11)) | C16: Suppressed in the dominance quadrants by HTA reporting convention, matching markov_cost_effectiveness.
A17: NMB at WTP | B17: =wtp*B11-B10 | C17: Net monetary benefit. Positive = worth doing at the threshold.
A19: Verdict | B19: =IF(B14="YES","dominant (cheaper and more effective)",IF(B15="YES","dominated (costlier and less effective)",IF(B17>=0,"cost-effective at WTP","not cost-effective at WTP")))
A21: Model note | B21: Discrete-time Markov cohort model, annual cycles, half-cycle correction, p = 1 - exp(-rate*dt), age-dependent Gompertz competing mortality, 3% discounting of costs and QALYs. Mirrors econ/markov.py. Sonnenberg & Beck (1993); Briggs, Sculpher & Claxton (2006).

Sheet Inputs
A1: GenomeLens - Markov cost-effectiveness model
A2: Yellow cells are inputs: edit them and every figure on Results recalculates. Nothing here is a pasted Python result.
A4: Parameter | B4: Value | C4: Units | D4: Note
A5: start_age | B5: 40 | C5: years | D5: Cohort age at cycle 0
A6: cycles | B6: 45 | C6: cycles | D6: Annual cycles. Lowering this works; raising it needs a re-export.
A7: incidence_rate | B7: 0.01 | C7: per year | D7: Well -> Disease hazard RATE (not a probability)
A8: rrr_intervention | B8: 0.3 | C8: fraction | D8: Relative risk reduction applied to incidence in the guided arm
A9: cost_intervention_annual | B9: 250 | C9: $/yr | D9: Paid while the patient remains Well, guided arm only
A10: cost_disease_annual | B10: 12000 | C10: $/yr | D10: Annual cost in the Disease state
A11: cost_well_annual | B11: 0 | C11: $/yr | D11: Annual cost in the Well state, both arms
A12: utility_well | B12: 0.9 | C12: QALY/yr | D12: Health-related quality of life, Well
A13: utility_disease | B13: 0.68 | C13: QALY/yr | D13: Health-related quality of life, Disease
A14: excess_mortality_rate | B14: 0.035 | C14: per year | D14: Disease-attributable excess mortality RATE
A15: discount_rate | B15: 0.03 | C15: per year | D15: Applied to both costs and QALYs
A16: wtp | B16: 100000 | C16: $/QALY | D16: Cost-effectiveness threshold
... A20: half_cycle | B20: 1 | C20: 1=on 0=off | D20: Weight cycle 0 and the final cycle at 0.5

Sheet Trace_SC
A1: Standard care - cohort trace (Well / Disease / Dead)
A3: cycle | B3: age | C3: incidence (eff. rate) | D3: p_wd raw | E3: p_bg raw | F3: p_ex | G3: p_wd norm | H3: p_bg norm | I3: p_dd | J3: Well | K3: Disease | L3: Dead | M3: cost/cycle | N3: qaly/cycle | O3: ly/cycle | P3: weight | Q3: discount | R3: disc. cost | S3: disc. qaly | T3: disc. ly
A4: 0 | B4: =start_age+0 | C4: =incidence_rate | D4: =1-EXP(-C4*cycle_length) | E4: =1-EXP(-(gompertz_a*EXP(gompertz_b*MAX(0,B4-20)))*cycle_length) | F4: =1-EXP(-excess_mortality_rate*cycle_length) | G4: =IF((D4+E4)>1,D4/(D4+E4),D4) | H4: =IF((D4+E4)>1,E4/(D4+E4),E4) | I4: =MIN(1,E4+F4) | J4: 1 | K4: 0 | L4: 0 | M4: =J4*(cost_well_annual)+K4*cost_disease_annual | N4: =J4*utility_well+K4*utility_disease | O4: =J4+K4 | P4: =IF(A4>cycles-1,0,IF(AND(half_cycle=1,OR(A4=0,A4=cycles-1)),0.5,1)) | Q4: =1/(1+discount_rate)^A4 | R4: =M4*P4*Q4 | S4: =N4*P4*Q4 | T4: =O4*P4*Q4
A5: 1 | B5: =start_age+1 | C5: =incidence_rate | D5: =1-EXP(-C5*cycle_length) | E5: =1-EXP(-(gompertz_a*EXP(gompertz_b*MAX(0,B5-20)))*cycle_length) | F5: =1-EXP(-excess_mortality_rate*cycle_length) | G5: =IF((D5+E5)>1,D5/(D5+E5),D5) | H5: =IF((D5+E5)>1,E5/(D5+E5),E5) | I5: =MIN(1,E5+F5) | J5: =J4*(1-G4-H4) | K5: =J4*G4+K4*(1-I4) | L5: =L4+J4*H4+K4*I4 | M5: =J5*(cost_well_annual)+K5*cost_disease_annual | N5: =J5*utility_well+K5*utility_disease | O5: =J5+K5 | P5: =IF(A5>cycles-1,0,IF(AND(half_cycle=1,OR(A5=0,A5=cycles-1)),0.5,1)) | Q5: =1/(1+discount_rate)^A5 | R5: =M5*P5*Q5 | S5: =N5*P5*Q5 | T5: =O5*P5*Q5
A6: 2 | B6: =start_age+2 | C6: =incidence_rate | D6: =1-EXP(-C6*cycle_length) | E6: =1-EXP(-(gompertz_a*EXP(gompertz_b*MAX(0,B6-20)))*cycle_length) | F6: =1-EXP(-excess_mortality_rate*cycle_length) | G6: =IF((D6+E6)>1,D6/(D6+E6),D6) | H6: =IF((D6+E6)>1,E6/(D6+E6),E6) | I6: =MIN(1,E6+F6) | J6: =J5*(1-G5-H5) | K6: =J5*G5+K5*(1-I5) | L6: =L5+J5*H5+K5*I5 | M6: =J6*(cost_well_annual)+K6*cost_disease_annual | N6: =J6*utility_well+K6*utility_disease | O6: =J6+K6 | P6: =IF(A6>cycles-1,0,IF(AND(half_cycle=1,OR(A6=0,A6=cycles-1)),0.5,1)) | Q6: =1/(1+discount_rate)^A6 | R6: =M6*P6*Q6 | S6: =N6*P6*Q6 | T6: =O6*P6*Q6
A7: 3 | B7: =start_age+3 | C7: =incidence_rate | D7: =1-EXP(-C7*cycle_length) | E7: =1-EXP(-(gompertz_a*EXP(gompertz_b*MAX(0,B7-20)))*cycle_length) | F7: =1-EXP(-excess_mortality_rate*cycle_length) | G7: =IF((D7+E7)>1,D7/(D7+E7),D7) | H7: =IF((D7+E7)>1,E7/(D7+E7),E7) | I7: =MIN(1,E7+F7) | J7: =J6*(1-G6-H6) | K7: =J6*G6+K6*(1-I6) | L7: =L6+J6*H6+K6*I6 | M7: =J7*(cost_well_annual)+K7*cost_disease_annual | N7: =J7*utility_well+K7*utility_disease | O7: =J7+K7 | P7: =IF(A7>cycles-1,0,IF(AND(half_cycle=1,OR(A7=0,A7=cycles-1)),0.5,1)) | Q7: =1/(1+discount_rate)^A7 | R7: =M7*P7*Q7 | S7: =N7*P7*Q7 | T7: =O7*P7*Q7
A8: 4 | B8: =start_age+4 | C8: =incidence_rate | D8: =1-EXP(-C8*cycle_length) | E8: =1-EXP(-(gompertz_a*EXP(gompertz_b*MAX(0,B8-20)))*cycle_length) | F8: =1-EXP(-excess_mortality_rate*cycle_length) | G8: =IF((D8+E8)>1,D8/(D8+E8),D8) | H8: =IF((D8+E8)>1,E8/(D8+E8),E8) | I8: =MIN(1,E8+F8) | J8: =J7*(1-G7-H7) | K8: =J7*G7+K7*(1-I7) | L8: =L7+J7*H7+K7*I7 | M8: =J8*(cost_well_annual)+K8*cost_disease_annual | N8: =J8*utility_well+K8*utility_disease | O8: =J8+K8 | P8: =IF(A8>cycles-1,0,IF(AND(half_cycle=1,OR(A8=0,A8=cycles-1)),0.5,1)) | Q8: =1/(1+discount_rate)^A8 | R8: =M8*P8*Q8 | S8: =N8*P8*Q8 | T8: =O8*P8*Q8
A9: 5 | B9: =start_age+5 | C9: =incidence_rate | D9: =1-EXP(-C9*cycle_length) | E9: =1-EXP(-(gompertz_a*EXP(gompertz_b*MAX(0,B9-20)))*cycle_length) | F9: =1-EXP(-excess_mortality_rate*cycle_length) | G9: =IF((D9+E9)>1,D9/(D9+E9),D9) | H9: =IF((D9+E9)>1,E9/(D9+E9),E9) | I9: =MIN(1,E9+F9) | J9: =J8*(1-G8-H8) | K9: =J8*G8+K8*(1-I8) | L9: =L8+J8*H8+K8*I8 | M9: =J9*(cost_well_annual)+K9*cost_disease_annual | N9: =J9*utility_well+K9*utility_disease | O9: =J9+K9 | P9: =IF(A9>cycles-1,0,IF(AND(half_cycle=1,OR(A9=0,A9=cycles-1)),0.5,1)) | Q9: =1/(1+discount_rate)^A9 | R9: =M9*P9*Q9 | S9: =N9*P9*Q9 | T9: =O9*P9*Q9
A10: 6 | B10: =start_age+6 | C10: =incidence_rate | D10: =1-EXP(-C10*cycle_length) | E10: =1-EXP(-(gompertz_a*EXP(gompertz_b*MAX(0,B10-20)))*cycle_length) | F10: =1-EXP(-excess_mortality_rate*cycle_length) | G10: =IF((D10+E10)>1,D10/(D10+E10),D10) | H10: =IF((D10+E10)>1,E10/(D10+E10),E10) | I10: =MIN(1,E10+F10) | J10: =J9*(1-G9-H9) | K10: =J9*G9+K9*(1-I9) | L10: =L9+J9*H9+K9*I9 | M10: =J10*(cost_well_annual)+K10*cost_disease_annual | N10: =J10*utility_well+K10*utility_disease | O10: =J10+K10 | P10: =IF(A10>cycles-1,0,IF(AND(half_cycle=1,OR(A10=0,A10=cycles-1)),0.5,1)) | Q10: =1/(1+discount_rate)^A10 | R10: =M10*P10*Q10 | S10: =N10*P10*Q10 | T10: =O10*P10*Q10
A11: 7 | B11: =start_age+7 | C11: =incidence_rate | D11: =1-EXP(-C11*cycle_length) | E11: =1-EXP(-(gompertz_a*EXP(gompertz_b*MAX(0,B11-20)))*cycle_length) | F11: =1-EXP(-excess_mortality_rate*cycle_length) | G11: =IF((D11+E11)>1,D11/(D11+E11),D11) | H11: =IF((D11+E11)>1,E11/(D11+E11),E11) | I11: =MIN(1,E11+F11) | J11: =J10*(1-G10-H10) | K11: =J10*G10+K10*(1-I10) | L11: =L10+J10*H10+K10*I10 | M11: =J11*(cost_well_annual)+K11*cost_disease_annual | N11: =J11*utility_well+K11*utility_disease | O11: =J11+K11 | P11: =IF(A11>cycles-1,0,IF(AND(half_cycle=1,OR(A11=0,A11=cycles-1)),0.5,1)) | Q11: =1/(1+discount_rate)^A11 | R11: =M11*P11*Q11 | S11: =N11*P11*Q11 | T11: =O11*P11*Q11
A12: 8 | B12: =start_age+8 | C12: =incidence_rate | D12: =1-EXP(-C12*cycle_length) | E12: =1-EXP(-(gompertz_a*EXP(gompertz_b*MAX(0,B12-20)))*cycle_length) | F12: =1-EXP(-excess_mortality_rate*cycle_length) | G12: =IF((D12+E12)>1,D12/(D12+E12),D12) | H12: =IF((D12+E12)>1,E12/(D12+E12),E12) | I12: =MIN(1,E12+F12) | J12: =J11*(1-G11-H11) | K12: =J11*G11+K11*(1-I11) | L12: =L11+J11*H11+K11*I11 | M12: =J12*(cost_well_annual)+K12*cost_disease_annual | N12: =J12*utility_well+K12*utility_disease | O12: =J12+K12 | P12: =IF(A12>cycles-1,0,IF(AND(half_cycle=1,OR(A12=0,A12=cycles-1)),0.5,1)) | Q12: =1/(1+discount_rate)^A12 | R12: =M12*P12*Q12 | S12: =N12*P12*Q12 | T12: =O12*P12*Q12
A13: 9 | B13: =start_age+9 | C13: =incidence_rate | D13: =1-EXP(-C13*cycle_length) | E13: =1-EXP(-(gompertz_a*EXP(gompertz_b*MAX(0,B13-20)))*cycle_length) | F13: =1-EXP(-excess_mortality_rate*cycle_length) | G13: =IF((D13+E13)>1,D13/(D13+E13),D13) | H13: =IF((D13+E13)>1,E13/(D13+E13),E13) | I13: =MIN(1,E13+F13) | J13: =J12*(1-G12-H12) | K13: =J12*G12+K12*(1-I12) | L13: =L12+J12*H12+K12*I12 | M13: =J13*(cost_well_annual)+K13*cost_disease_annual | N13: =J13*utility_well+K13*utility_disease | O13: =J13+K13 | P13: =IF(A13>cycles-1,0,IF(AND(half_cycle=1,OR(A13=0,A13=cycles-1)),0.5,1)) | Q13: =1/(1+discount_rate)^A13 | R13: =M13*P13*Q13 | S13: =N13*P13*Q13 | T13: =O13*P13*Q13
A14: 10 | B14: =start_age+10 | C14: =incidence_rate | D14: =1-EXP(-C14*cycle_length) | E14: =1-EXP(-(gompertz_a*EXP(gompertz_b*MAX(0,B14-20)))*cycle_length) | F14: =1-EXP(-excess_mortality_rate*cycle_length) | G14: =IF((D14+E14)>1,D14/(D14+E14),D14) | H14: =IF((D14+E14)>1,E14/(D14+E14),E14) | I14: =MIN(1,E14+F14) | J14: =J13*(1-G13-H13) | K14: =J13*G13+K13*(1-I13) | L14: =L13+J13*H13+K13*I13 | M14: =J14*(cost_well_annual)+K14*cost_disease_annual | N14: =J14*utility_well+K14*utility_disease | O14: =J14+K14 | P14: =IF(A14>cycles-1,0,IF(AND(half_cycle=1,OR(A14=0,A14=cycles-1)),0.5,1)) | Q14: =1/(1+discount_rate)^A14 | R14: =M14*P14*Q14 | S14: =N14*P14*Q14 | T14: =O14*P14*Q14
A15: 11 | B15: =start_age+11 | C15: =incidence_rate | D15: =1-EXP(-C15*cycle_length) | E15: =1-EXP(-(gompertz_a*EXP(gompertz_b*MAX(0,B15-20)))*cycle_length) | F15: =1-EXP(-excess_mortality_rate*cycle_length) | G15: =IF((D15+E15)>1,D15/(D15+E15),D15) | H15: =IF((D15+E15)>1,E15/(D15+E15),E15) | I15: =MIN(1,E15+F15) | J15: =J14*(1-G14-H14) | K15: =J14*G14+K14*(1-I14) | L15: =L14+J14*H14+K14*I14 | M15: =J15*(cost_well_annual)+K15*cost_disease_annual | N15: =J15*utility_well+K15*utility_disease | O15: =J15+K15 | P15: =IF(A15>cycles-1,0,IF(AND(half_cycle=1,OR(A15=0,A15=cycles-1)),0.5,1)) | Q15: =1/(1+discount_rate)^A15 | R15: =M15*P15*Q15 | S15: =N15*P15*Q15 | T15: =O15*P15*Q15
A16: 12 | B16: =start_age+12 | C16: =incidence_rate | D16: =1-EXP(-C16*cycle_length) | E16: =1-EXP(-(gompertz_a*EXP(gompertz_b*MAX(0,B16-20)))*cycle_length) | F16: =1-EXP(-excess_mortality_rate*cycle_length) | G16: =IF((D16+E16)>1,D16/(D16+E16),D16) | H16: =IF((D16+E16)>1,E16/(D16+E16),E16) | I16: =MIN(1,E16+F16) | J16: =J15*(1-G15-H15) | K16: =J15*G15+K15*(1-I15) | L16: =L15+J15*H15+K15*I15 | M16: =J16*(cost_well_annual)+K16*cost_disease_annual | N16: =J16*utility_well+K16*utility_disease | O16: =J16+K16 | P16: =IF(A16>cycles-1,0,IF(AND(half_cycle=1,OR(A16=0,A16=cycles-1)),0.5,1)) | Q16: =1/(1+discount_rate)^A16 | R16: =M16*P16*Q16 | S16: =N16*P16*Q16 | T16: =O16*P16*Q16
A17: 13 | B17: =start_age+13 | C17: =incidence_rate | D17: =1-EXP(-C17*cycle_length) | E17: =1-EXP(-(gompertz_a*EXP(gompertz_b*MAX(0,B17-20)))*cycle_length) | F17: =1-EXP(-excess_mortality_rate*cycle_length) | G17: =IF((D17+E17)>1,D17/(D17+E17),D17) | H17: =IF((D17+E17)>1,E17/(D17+E17),E17) | I17: =MIN(1,E17+F17) | J17: =J16*(1-G16-H16) | K17: =J16*G16+K16*(1-I16) | L17: =L16+J16*H16+K16*I16 | M17: =J17*(cost_well_annual)+K17*cost_disease_annual | N17: =J17*utility_well+K17*utility_disease | O17: =J17+K17 | P17: =IF(A17>cycles-1,0,IF(AND(half_cycle=1,OR(A17=0,A17=cycles-1)),0.5,1)) | Q17: =1/(1+discount_rate)^A17 | R17: =M17*P17*Q17 | S17: =N17*P17*Q17 | T17: =O17*P17*Q17
A18: 14 | B18: =start_age+14 | C18: =incidence_rate | D18: =1-EXP(-C18*cycle_length) | E18: =1-EXP(-(gompertz_a*EXP(gompertz_b*MAX(0,B18-20)))*cycle_length) | F18: =1-EXP(-excess_mortality_rate*cycle_length) | G18: =IF((D18+E18)>1,D18/(D18+E18),D18) | H18: =IF((D18+E18)>1,E18/(D18+E18),E18) | I18: =MIN(1,E18+F18) | J18: =J17*(1-G17-H17) | K18: =J17*G17+K17*(1-I17) | L18: =L17+J17*H17+K17*I17 | M18: =J18*(cost_well_annual)+K18*cost_disease_annual | N18: =J18*utility_well+K18*utility_disease | O18: =J18+K18 | P18: =IF(A18>cycles-1,0,IF(AND(half_cycle=1,OR(A18=0,A18=cycles-1)),0.5,1)) | Q18: =1/(1+discount_rate)^A18 | R18: =M18*P18*Q18 | S18: =N18*P18*Q18 | T18: =O18*P18*Q18
A19: 15 | B19: =start_age+15 | C19: =incidence_rate | D19: =1-EXP(-C19*cycle_length) | E19: =1-EXP(-(gompertz_a*EXP(gompertz_b*MAX(0,B19-20)))*cycle_length) | F19: =1-EXP(-excess_mortality_rate*cycle_length) | G19: =IF((D19+E19)>1,D19/(D19+E19),D19) | H19: =IF((D19+E19)>1,E19/(D19+E19),E19) | I19: =MIN(1,E19+F19) | J19: =J18*(1-G18-H18) | K19: =J18*G18+K18*(1-I18) | L19: =L18+J18*H18+K18*I18 | M19: =J19*(cost_well_annual)+K19*cost_disease_annual | N19: =J19*utility_well+K19*utility_disease | O19: =J19+K19 | P19: =IF(A19>cycles-1,0,IF(AND(half_cycle=1,OR(A19=0,A19=cycles-1)),0.5,1)) | Q19: =1/(1+discount_rate)^A19 | R19: =M19*P19*Q19 | S19: =N19*P19*Q19 | T19: =O19*P19*Q19
A20: 16 | B20: =start_age+16 | C20: =incidence_rate | D20: =1-EXP(-C20*cycle_length) | E20: =1-EXP(-(gompertz_a*EXP(gompertz_b*MAX(0,B20-20)))*cycle_length) | F20: =1-EXP(-excess_mortality_rate*cycle_length) | G20: =IF((D20+E20)>1,D20/(D20+E20),D20) | H20: =IF((D20+E20)>1,E20/(D20+E20),E20) | I20: =MIN(1,E20+F20) | J20: =J19*(1-G19-H19) | K20: =J19*G19+K19*(1-I19) | L20: =L19+J19*H19+K19*I19 | M20: =J20*(cost_well_annual)+K20*cost_disease_annual | N20: =J20*utility_well+K20*utility_disease | O20: =J20+K20 | P20: =IF(A20>cycles-1,0,IF(AND(half_cycle=1,OR(A20=0,A20=cycles-1)),0.5,1)) | Q20: =1/(1+discount_rate)^A20 | R20: =M20*P20*Q20 | S20: =N20*P20*Q20 | T20: =O20*P20*Q20
A21: 17 | B21: =start_age+17 | C21: =incidence_rate | D21: =1-EXP(-C21*cycle_length) | E21: =1-EXP(-(gompertz_a*EXP(gompertz_b*MAX(0,B21-20)))*cycle_length) | F21: =1-EXP(-excess_mortality_rate*cycle_length) | G21: =IF((D21+E21)>1,D21/(D21+E21),D21) | H21: =IF((D21+E21)>1,E21/(D21+E21),E21) | I21: =MIN(1,E21+F21) | J21: =J20*(1-G20-H20) | K21: =J20*G20+K20*(1-I20) | L21: =L20+J20*H20+K20*I20 | M21: =J21*(cost_well_annual)+K21*cost_disease_annual | N21: =J21*utility_well+K21*utility_disease | O21: =J21+K21 | P21: =IF(A21>cycles-1,0,IF(AND(half_cycle=1,OR(A21=0,A21=cycles-1)),0.5,1)) | Q21: =1/(1+discount_rate)^A21 | R21: =M21*P21*Q21 | S21: =N21*P21*Q21 | T21: =O21*P21*Q21
A22: 18 | B22: =start_age+18 | C22: =incidence_rate | D22: =1-EXP(-C22*cycle_length) | E22: =1-EXP(-(gompertz_a*EXP(gompertz_b*MAX(0,B22-20)))*cycle_length) | F22: =1-EXP(-excess_mortality_rate*cycle_length) | G22: =IF((D22+E22)>1,D22/(D22+E22),D22) | H22: =IF((D22+E22)>1,E22/(D22+E22),E22) | I22: =MIN(1,E22+F22) | J22: =J21*(1-G21-H21) | K22: =J21*G21+K21*(1-I21) | L22: =L21+J21*H21+K21*I21 | M22: =J22*(cost_well_annual)+K22*cost_disease_annual | N22: =J22*utility_well+K22*utility_disease | O22: =J22+K22 | P22: =IF(A22>cycles-1,0,IF(AND(half_cycle=1,OR(A22=0,A22=cycles-1)),0.5,1)) | Q22: =1/(1+discount_rate)^A22 | R22: =M22*P22*Q22 | S22: =N22*P22*Q22 | T22: =O22*P22*Q22
A23: 19 | B23: =start_age+19 | C23: =incidence_rate | D23: =1-EXP(-C23*cycle_length) | E23: =1-EXP(-(gompertz_a*EXP(gompertz_b*MAX(0,B23-20)))*cycle_length) | F23: =1-EXP(-excess_mortality_rate*cycle_length) | G23: =IF((D23+E23)>1,D23/(D23+E23),D23) | H23: =IF((D23+E23)>1,E23/(D23+E23),E23) | I23: =MIN(1,E23+F23) | J23: =J22*(1-G22-H22) | K23: =J22*G22+K22*(1-I22) | L23: =L22+J22*H22+K22*I22 | M23: =J23*(cost_well_annual)+K23*cost_disease_annual | N23: =J23*utility_well+K23*utility_disease | O23: =J23+K23 | P23: =IF(A23>cycles-1,0,IF(AND(half_cycle=1,OR(A23=0,A23=cycles-1)),0.5,1)) | Q23: =1/(1+discount_rate)^A23 | R23: =M23*P23*Q23 | S23: =N23*P23*Q23 | T23: =O23*P23*Q23
A24: 20 | B24: =start_age+20 | C24: =incidence_rate | D24: =1-EXP(-C24*cycle_length) | E24: =1-EXP(-(gompertz_a*EXP(gompertz_b*MAX(0,B24-20)))*cycle_length) | F24: =1-EXP(-excess_mortality_rate*cycle_length) | G24: =IF((D24+E24)>1,D24/(D24+E24),D24) | H24: =IF((D24+E24)>1,E24/(D24+E24),E24) | I24: =MIN(1,E24+F24) | J24: =J23*(1-G23-H23) | K24: =J23*G23+K23*(1-I23) | L24: =L23+J23*H23+K23*I23 | M24: =J24*(cost_well_annual)+K24*cost_disease_annual | N24: =J24*utility_well+K24*utility_disease | O24: =J24+K24 | P24: =IF(A24>cycles-1,0,IF(AND(half_cycle=1,OR(A24=0,A24=cycles-1)),0.5,1)) | Q24: =1/(1+discount_rate)^A24 | R24: =M24*P24*Q24 | S24: =N24*P24*Q24 | T24: =O24*P24*Q24
A25: 21 | B25: =start_age+21 | C25: =incidence_rate | D25: =1-EXP(-C25*cycle_length) | E25: =1-EXP(-(gompertz_a*EXP(gompertz_b*MAX(0,B25-20)))*cycle_length) | F25: =1-EXP(-excess_mortality_rate*cycle_length) | G25: =IF((D25+E25)>1,D25/(D25+E25),D25) | H25: =IF((D25+E25)>1,E25/(D25+E25),E25) | I25: =MIN(1,E25+F25) | J25: =J24*(1-G24-H24) | K25: =J24*G24+K24*(1-I24) | L25: =L24+J24*H24+K24*I24 | M25: =J25*(cost_well_annual)+K25*cost_disease_annual | N25: =J25*utility_well+K25*utility_disease | O25: =J25+K25 | P25: =IF(A25>cycles-1,0,IF(AND(half_cycle=1,OR(A25=0,A25=cycles-1)),0.5,1)) | Q25: =1/(1+discount_rate)^A25 | R25: =M25*P25*Q25 | S25: =N25*P25*Q25 | T25: =O25*P25*Q25
A26: 22 | B26: =start_age+22 | C26: =incidence_rate | D26: =1-EXP(-C26*cycle_length) | E26: =1-EXP(-(gompertz_a*EXP(gompertz_b*MAX(0,B26-20)))*cycle_length) | F26: =1-EXP(-excess_mortality_rate*cycle_length) | G26: =IF((D26+E26)>1,D26/(D26+E26),D26) | H26: =IF((D26+E26)>1,E26/(D26+E26),E26) | I26: =MIN(1,E26+F26) | J26: =J25*(1-G25-H25) | K26: =J25*G25+K25*(1-I25) | L26: =L25+J25*H25+K25*I25 | M26: =J26*(cost_well_annual)+K26*cost_disease_annual | N26: =J26*utility_well+K26*utility_disease | O26: =J26+K26 | P26: =IF(A26>cycles-1,0,IF(AND(half_cycle=1,OR(A26=0,A26=cycles-1)),0.5,1)) | Q26: =1/(1+discount_rate)^A26 | R26: =M26*P26*Q26 | S26: =N26*P26*Q26 | T26: =O26*P26*Q26
A27: 23 | B27: =start_age+23 | C27: =incidence_rate | D27: =1-EXP(-C27*cycle_length) | E27: =1-EXP(-(gompertz_a*EXP(gompertz_b*MAX(0,B27-20)))*cycle_length) | F27: =1-EXP(-excess_mortality_rate*cycle_length) | G27: =IF((D27+E27)>1,D27/(D27+E27),D27) | H27: =IF((D27+E27)>1,E27/(D27+E27),E27) | I27: =MIN(1,E27+F27) | J27: =J26*(1-G26-H26) | K27: =J26*G26+K26*(1-I26) | L27: =L26+J26*H26+K26*I26 | M27: =J27*(cost_well_annual)+K27*cost_disease_annual | N27: =J27*utility_well+K27*utility_disease | O27: =J27+K27 | P27: =IF(A27>cycles-1,0,IF(AND(half_cycle=1,OR(A27=0,A27=cycles-1)),0.5,1)) | Q27: =1/(1+discount_rate)^A27 | R27: =M27*P27*Q27 | S27: =N27*P27*Q27 | T27: =O27*P27*Q27
A28: 24 | B28: =start_age+24 | C28: =incidence_rate | D28: =1-EXP(-C28*cycle_length) | E28: =1-EXP(-(gompertz_a*EXP(gompertz_b*MAX(0,B28-20)))*cycle_length) | F28: =1-EXP(-excess_mortality_rate*cycle_length) | G28: =IF((D28+E28)>1,D28/(D28+E28),D28) | H28: =IF((D28+E28)>1,E28/(D28+E28),E28) | I28: =MIN(1,E28+F28) | J28: =J27*(1-G27-H27) | K28: =J27*G27+K27*(1-I27) | L28: =L27+J27*H27+K27*I27 | M28: =J28*(cost_well_annual)+K28*cost_disease_annual | N28: =J28*utility_well+K28*utility_disease | O28: =J28+K28 | P28: =IF(A28>cycles-1,0,IF(AND(half_cycle=1,OR(A28=0,A28=cycles-1)),0.5,1)) | Q28: =1/(1+discount_rate)^A28 | R28: =M28*P28*Q28 | S28: =N28*P28*Q28 | T28: =O28*P28*Q28
A29: 25 | B29: =start_age+25 | C29: =incidence_rate | D29: =1-EXP(-C29*cycle_length) | E29: =1-EXP(-(gompertz_a*EXP(gompertz_b*MAX(0,B29-20)))*cycle_length) | F29: =1-EXP(-excess_mortality_rate*cycle_length) | G29: =IF((D29+E29)>1,D29/(D29+E29),D29) | H29: =IF((D29+E29)>1,E29/(D29+E29),E29) | I29: =MIN(1,E29+F29) | J29: =J28*(1-G28-H28) | K29: =J28*G28+K28*(1-I28) | L29: =L28+J28*H28+K28*I28 | M29: =J29*(cost_well_annual)+K29*cost_disease_annual | N29: =J29*utility_well+K29*utility_disease | O29: =J29+K29 | P29: =IF(A29>cycles-1,0,IF(AND(half_cycle=1,OR(A29=0,A29=cycles-1)),0.5,1)) | Q29: =1/(1+discount_rate)^A29 | R29: =M29*P29*Q29 | S29: =N29*P29*Q29 | T29: =O29*P29*Q29
A30: 26 | B30: =start_age+26 | C30: =incidence_rate | D30: =1-EXP(-C30*cycle_length) | E30: =1-EXP(-(gompertz_a*EXP(gompertz_b*MAX(0,B30-20)))*cycle_length) | F30: =1-EXP(-excess_mortality_rate*cycle_length) | G30: =IF((D30+E30)>1,D30/(D30+E30),D30) | H30: =IF((D30+E30)>1,E30/(D30+E30),E30) | I30: =MIN(1,E30+F30) | J30: =J29*(1-G29-H29) | K30: =J29*G29+K29*(1-I29) | L30: =L29+J29*H29+K29*I29 | M30: =J30*(cost_well_annual)+K30*cost_disease_annual | N30: =J30*utility_well+K30*utility_disease | O30: =J30+K30 | P30: =IF(A30>cycles-1,0,IF(AND(half_cycle=1,OR(A30=0,A30=cycles-1)),0.5,1)) | Q30: =1/(1+discount_rate)^A30 | R30: =M30*P30*Q30 | S30: =N30*P30*Q30 | T30: =O30*P30*Q30
A31: 27 | B31: =start_age+27 | C31: =incidence_rate | D31: =1-EXP(-C31*cycle_length) | E31: =1-EXP(-(gompertz_a*EXP(gompertz_b*MAX(0,B31-20)))*cycle_length) | F31: =1-EXP(-excess_mortality_rate*cycle_length) | G31: =IF((D31+E31)>1,D31/(D31+E31),D31) | H31: =IF((D31+E31)>1,E31/(D31+E31),E31) | I31: =MIN(1,E31+F31) | J31: =J30*(1-G30-H30) | K31: =J30*G30+K30*(1-I30) | L31: =L30+J30*H30+K30*I30 | M31: =J31*(cost_well_annual)+K31*cost_disease_annual | N31: =J31*utility_well+K31*utility_disease | O31: =J31+K31 | P31: =IF(A31>cycles-1,0,IF(AND(half_cycle=1,OR(A31=0,A31=cycles-1)),0.5,1)) | Q31: =1/(1+discount_rate)^A31 | R31: =M31*P31*Q31 | S31: =N31*P31*Q31 | T31: =O31*P31*Q31
A32: 28 | B32: =start_age+28 | C32: =incidence_rate | D32: =1-EXP(-C32*cycle_length) | E32: =1-EXP(-(gompertz_a*EXP(gompertz_b*MAX(0,B32-20)))*cycle_length) | F32: =1-EXP(-excess_mortality_rate*cycle_length) | G32: =IF((D32+E32)>1,D32/(D32+E32),D32) | H32: =IF((D32+E32)>1,E32/(D32+E32),E32) | I32: =MIN(1,E32+F32) | J32: =J31*(1-G31-H31) | K32: =J31*G31+K31*(1-I31) | L32: =L31+J31*H31+K31*I31 | M32: =J32*(cost_well_annual)+K32*cost_disease_annual | N32: =J32*utility_well+K32*utility_disease | O32: =J32+K32 | P32: =IF(A32>cycles-1,0,IF(AND(half_cycle=1,OR(A32=0,A32=cycles-1)),0.5,1)) | Q32: =1/(1+discount_rate)^A32 | R32: =M32*P32*Q32 | S32: =N32*P32*Q32 | T32: =O32*P32*Q32
A33: 29 | B33: =start_age+29 | C33: =incidence_rate | D33: =1-EXP(-C33*cycle_length) | E33: =1-EXP(-(gompertz_a*EXP(gompertz_b*MAX(0,B33-20)))*cycle_length) | F33: =1-EXP(-excess_mortality_rate*cycle_length) | G33: =IF((D33+E33)>1,D33/(D33+E33),D33) | H33: =IF((D33+E33)>1,E33/(D33+E33),E33) | I33: =MIN(1,E33+F33) | J33: =J32*(1-G32-H32) | K33: =J32*G32+K32*(1-I32) | L33: =L32+J32*H32+K32*I32 | M33: =J33*(cost_well_annual)+K33*cost_disease_annual | N33: =J33*utility_well+K33*utility_disease | O33: =J33+K33 | P33: =IF(A33>cycles-1,0,IF(AND(half_cycle=1,OR(A33=0,A33=cycles-1)),0.5,1)) | Q33: =1/(1+discount_rate)^A33 | R33: =M33*P33*Q33 | S33: =N33*P33*Q33 | T33: =O33*P33*Q33
A34: 30 | B34: =start_age+30 | C34: =incidence_rate | D34: =1-EXP(-C34*cycle_length) | E34: =1-EXP(-(gompertz_a*EXP(gompertz_b*MAX(0,B34-20)))*cycle_length) | F34: =1-EXP(-excess_mortality_rate*cycle_length) | G34: =IF((D34+E34)>1,D34/(D34+E34),D34) | H34: =IF((D34+E34)>1,E34/(D34+E34),E34) | I34: =MIN(1,E34+F34) | J34: =J33*(1-G33-H33) | K34: =J33*G33+K33*(1-I33) | L34: =L33+J33*H33+K33*I33 | M34: =J34*(cost_well_annual)+K34*cost_disease_annual | N34: =J34*utility_well+K34*utility_disease | O34: =J34+K34 | P34: =IF(A34>cycles-1,0,IF(AND(half_cycle=1,OR(A34=0,A34=cycles-1)),0.5,1)) | Q34: =1/(1+discount_rate)^A34 | R34: =M34*P34*Q34 | S34: =N34*P34*Q34 | T34: =O34*P34*Q34
A35: 31 | B35: =start_age+31 | C35: =incidence_rate | D35: =1-EXP(-C35*cycle_length) | E35: =1-EXP(-(gompertz_a*EXP(gompertz_b*MAX(0,B35-20)))*cycle_length) | F35: =1-EXP(-excess_mortality_rate*cycle_length) | G35: =IF((D35+E35)>1,D35/(D35+E35),D35) | H35: =IF((D35+E35)>1,E35/(D35+E35),E35) | I35: =MIN(1,E35+F35) | J35: =J34*(1-G34-H34) | K35: =J34*G34+K34*(1-I34) | L35: =L34+J34*H34+K34*I34 | M35: =J35*(cost_well_annual)+K35*cost_disease_annual | N35: =J35*utility_well+K35*utility_disease | O35: =J35+K35 | P35: =IF(A35>cycles-1,0,IF(AND(half_cycle=1,OR(A35=0,A35=cycles-1)),0.5,1)) | Q35: =1/(1+discount_rate)^A35 | R35: =M35*P35*Q35 | S35: =N35*P35*Q35 | T35: =O35*P35*Q35
A36: 32 | B36: =start_age+32 | C36: =incidence_rate | D36: =1-EXP(-C36*cycle_length) | E36: =1-EXP(-(gompertz_a*EXP(gompertz_b*MAX(0,B36-20)))*cycle_length) | F36: =1-EXP(-excess_mortality_rate*cycle_length) | G36: =IF((D36+E36)>1,D36/(D36+E36),D36) | H36: =IF((D36+E36)>1,E36/(D36+E36),E36) | I36: =MIN(1,E36+F36) | J36: =J35*(1-G35-H35) | K36: =J35*G35+K35*(1-I35) | L36: =L35+J35*H35+K35*I35 | M36: =J36*(cost_well_annual)+K36*cost_disease_annual | N36: =J36*utility_well+K36*utility_disease | O36: =J36+K36 | P36: =IF(A36>cycles-1,0,IF(AND(half_cycle=1,OR(A36=0,A36=cycles-1)),0.5,1)) | Q36: =1/(1+discount_rate)^A36 | R36: =M36*P36*Q36 | S36: =N36*P36*Q36 | T36: =O36*P36*Q36
A37: 33 | B37: =start_age+33 | C37: =incidence_rate | D37: =1-EXP(-C37*cycle_length) | E37: =1-EXP(-(gompertz_a*EXP(gompertz_b*MAX(0,B37-20)))*cycle_length) | F37: =1-EXP(-excess_mortality_rate*cycle_length) | G37: =IF((D37+E37)>1,D37/(D37+E37),D37) | H37: =IF((D37+E37)>1,E37/(D37+E37),E37) | I37: =MIN(1,E37+F37) | J37: =J36*(1-G36-H36) | K37: =J36*G36+K36*(1-I36) | L37: =L36+J36*H36+K36*I36 | M37: =J37*(cost_well_annual)+K37*cost_disease_annual | N37: =J37*utility_well+K37*utility_disease | O37: =J37+K37 | P37: =IF(A37>cycles-1,0,IF(AND(half_cycle=1,OR(A37=0,A37=cycles-1)),0.5,1)) | Q37: =1/(1+discount_rate)^A37 | R37: =M37*P37*Q37 | S37: =N37*P37*Q37 | T37: =O37*P37*Q37
A38: 34 | B38: =start_age+34 | C38: =incidence_rate | D38: =1-EXP(-C38*cycle_length) | E38: =1-EXP(-(gompertz_a*EXP(gompertz_b*MAX(0,B38-20)))*cycle_length) | F38: =1-EXP(-excess_mortality_rate*cycle_length) | G38: =IF((D38+E38)>1,D38/(D38+E38),D38) | H38: =IF((D38+E38)>1,E38/(D38+E38),E38) | I38: =MIN(1,E38+F38) | J38: =J37*(1-G37-H37) | K38: =J37*G37+K37*(1-I37) | L38: =L37+J37*H37+K37*I37 | M38: =J38*(cost_well_annual)+K38*cost_disease_annual | N38: =J38*utility_well+K38*utility_disease | O38: =J38+K38 | P38: =IF(A38>cycles-1,0,IF(AND(half_cycle=1,OR(A38=0,A38=cycles-1)),0.5,1)) | Q38: =1/(1+discount_rate)^A38 | R38: =M38*P38*Q38 | S38: =N38*P38*Q38 | T38: =O38*P38*Q38
A39: 35 | B39: =start_age+35 | C39: =incidence_rate | D39: =1-EXP(-C39*cycle_length) | E39: =1-EXP(-(gompertz_a*EXP(gompertz_b*MAX(0,B39-20)))*cycle_length) | F39: =1-EXP(-excess_mortality_rate*cycle_length) | G39: =IF((D39+E39)>1,D39/(D39+E39),D39) | H39: =IF((D39+E39)>1,E39/(D39+E39),E39) | I39: =MIN(1,E39+F39) | J39: =J38*(1-G38-H38) | K39: =J38*G38+K38*(1-I38) | L39: =L38+J38*H38+K38*I38 | M39: =J39*(cost_well_annual)+K39*cost_disease_annual | N39: =J39*utility_well+K39*utility_disease | O39: =J39+K39 | P39: =IF(A39>cycles-1,0,IF(AND(half_cycle=1,OR(A39=0,A39=cycles-1)),0.5,1)) | Q39: =1/(1+discount_rate)^A39 | R39: =M39*P39*Q39 | S39: =N39*P39*Q39 | T39: =O39*P39*Q39
A40: 36 | B40: =start_age+36 | C40: =incidence_rate | D40: =1-EXP(-C40*cycle_length) | E40: =1-EXP(-(gompertz_a*EXP(gompertz_b*MAX(0,B40-20)))*cycle_length) | F40: =1-EXP(-excess_mortality_rate*cycle_length) | G40: =IF((D40+E40)>1,D40/(D40+E40),D40) | H40: =IF((D40+E40)>1,E40/(D40+E40),E40) | I40: =MIN(1,E40+F40) | J40: =J39*(1-G39-H39) | K40: =J39*G39+K39*(1-I39) | L40: =L39+J39*H39+K39*I39 | M40: =J40*(cost_well_annual)+K40*cost_disease_annual | N40: =J40*utility_well+K40*utility_disease | O40: =J40+K40 | P40: =IF(A40>cycles-1,0,IF(AND(half_cycle=1,OR(A40=0,A40=cycles-1)),0.5,1)) | Q40: =1/(1+discount_rate)^A40 | R40: =M40*P40*Q40 | S40: =N40*P40*Q40 | T40: =O40*P40*Q40
A41: 37 | B41: =start_age+37 | C41: =incidence_rate | D41: =1-EXP(-C41*cycle_length) | E41: =1-EXP(-(gompertz_a*EXP(gompertz_b*MAX(0,B41-20)))*cycle_length) | F41: =1-EXP(-excess_mortality_rate*cycle_length) | G41: =IF((D41+E41)>1,D41/(D41+E41),D41) | H41: =IF((D41+E41)>1,E41/(D41+E41),E41) | I41: =MIN(1,E41+F41) | J41: =J40*(1-G40-H40) | K41: =J40*G40+K40*(1-I40) | L41: =L40+J40*H40+K40*I40 | M41: =J41*(cost_well_annual)+K41*cost_disease_annual | N41: =J41*utility_well+K41*utility_disease | O41: =J41+K41 | P41: =IF(A41>cycles-1,0,IF(AND(half_cycle=1,OR(A41=0,A41=cycles-1)),0.5,1)) | Q41: =1/(1+discount_rate)^A41 | R41: =M41*P41*Q41 | S41: =N41*P41*Q41 | T41: =O41*P41*Q41
...

Sheet Trace_GG
A1: Genomic-guided - cohort trace (Well / Disease / Dead)
A3: cycle | B3: age | C3: incidence (eff. rate) | D3: p_wd raw | E3: p_bg raw | F3: p_ex | G3: p_wd norm | H3: p_bg norm | I3: p_dd | J3: Well | K3: Disease | L3: Dead | M3: cost/cycle | N3: qaly/cycle | O3: ly/cycle | P3: weight | Q3: discount | R3: disc. cost | S3: disc. qaly | T3: disc. ly
A4: 0 | B4: =start_age+0 | C4: =incidence_rate*(1-rrr_intervention) | D4: =1-EXP(-C4*cycle_length) | E4: =1-EXP(-(gompertz_a*EXP(gompertz_b*MAX(0,B4-20)))*cycle_length) | F4: =1-EXP(-excess_mortality_rate*cycle_length) | G4: =IF((D4+E4)>1,D4/(D4+E4),D4) | H4: =IF((D4+E4)>1,E4/(D4+E4),E4) | I4: =MIN(1,E4+F4) | J4: 1 | K4: 0 | L4: 0 | M4: =J4*(cost_well_annual+cost_intervention_annual)+K4*cost_disease_annual | N4: =J4*utility_well+K4*utility_disease | O4: =J4+K4 | P4: =IF(A4>cycles-1,0,IF(AND(half_cycle=1,OR(A4=0,A4=cycles-1)),0.5,1)) | Q4: =1/(1+discount_rate)^A4 | R4: =M4*P4*Q4 | S4: =N4*P4*Q4 | T4: =O4*P4*Q4
A5: 1 | B5: =start_age+1 | C5: =incidence_rate*(1-rrr_intervention) | D5: =1-EXP(-C5*cycle_length) | E5: =1-EXP(-(gompertz_a*EXP(gompertz_b*MAX(0,B5-20)))*cycle_length) | F5: =1-EXP(-excess_mortality_rate*cycle_length) | G5: =IF((D5+E5)>1,D5/(D5+E5),D5) | H5: =IF((D5+E5)>1,E5/(D5+E5),E5) | I5: =MIN(1,E5+F5) | J5: =J4*(1-G4-H4) | K5: =J4*G4+K4*(1-I4) | L5: =L4+J4*H4+K4*I4 | M5: =J5*(cost_well_annual+cost_intervention_annual)+K5*cost_disease_annual | N5: =J5*utility_well+K5*utility_disease | O5: =J5+K5 | P5: =IF(A5>cycles-1,0,IF(AND(half_cycle=1,OR(A5=0,A5=cycles-1)),0.5,1)) | Q5: =1/(1+discount_rate)^A5 | R5: =M5*P5*Q5 | S5: =N5*P5*Q5 | T5: =O5*P5*Q5
A6: 2 | B6: =start_age+2 | C6: =incidence_rate*(1-rrr_intervention) | D6: =1-EXP(-C6*cycle_length) | E6: =1-EXP(-(gompertz_a*EXP(gompertz_b*MAX(0,B6-20)))*cycle_length) | F6: =1-EXP(-excess_mortality_rate*cycle_length) | G6: =IF((D6+E6)>1,D6/(D6+E6),D6) | H6: =IF((D6+E6)>1,E6/(D6+E6),E6) | I6: =MIN(1,E6+F6) | J6: =J5*(1-G5-H5) | K6: =J5*G5+K5*(1-I5) | L6: =L5+J5*H5+K5*I5 | M6: =J6*(cost_well_annual+cost_intervention_annual)+K6*cost_disease_annual | N6: =J6*utility_well+K6*utility_disease | O6: =J6+K6 | P6: =IF(A6>cycles-1,0,IF(AND(half_cycle=1,OR(A6=0,A6=cycles-1)),0.5,1)) | Q6: =1/(1+discount_rate)^A6 | R6: =M6*P6*Q6 | S6: =N6*P6*Q6 | T6: =O6*P6*Q6
A7: 3 | B7: =start_age+3 | C7: =incidence_rate*(1-rrr_intervention) | D7: =1-EXP(-C7*cycle_length) | E7: =1-EXP(-(gompertz_a*EXP(gompertz_b*MAX(0,B7-20)))*cycle_length) | F7: =1-EXP(-excess_mortality_rate*cycle_length) | G7: =IF((D7+E7)>1,D7/(D7+E7),D7) | H7: =IF((D7+E7)>1,E7/(D7+E7),E7) | I7: =MIN(1,E7+F7) | J7: =J6*(1-G6-H6) | K7: =J6*G6+K6*(1-I6) | L7: =L6+J6*H6+K6*I6 | M7: =J7*(cost_well_annual+cost_intervention_annual)+K7*cost_disease_annual | N7: =J7*utility_well+K7*utility_disease | O7: =J7+K7 | P7: =IF(A7>cycles-1,0,IF(AND(half_cycle=1,OR(A7=0,A7=cycles-1)),0.5,1)) | Q7: =1/(1+discount_rate)^A7 | R7: =M7*P7*Q7 | S7: =N7*P7*Q7 | T7: =O7*P7*Q7
A8: 4 | B8: =start_age+4 | C8: =incidence_rate*(1-rrr_intervention) | D8: =1-EXP(-C8*cycle_length) | E8: =1-EXP(-(gompertz_a*EXP(gompertz_b*MAX(0,B8-20)))*cycle_length) | F8: =1-EXP(-excess_mortality_rate*cycle_length) | G8: =IF((D8+E8)>1,D8/(D8+E8),D8) | H8: =IF((D8+E8)>1,E8/(D8+E8),E8) | I8: =MIN(1,E8+F8) | J8: =J7*(1-G7-H7) | K8: =J7*G7+K7*(1-I7) | L8: =L7+J7*H7+K7*I7 | M8: =J8*(cost_well_annual+cost_intervention_annual)+K8*cost_disease_annual | N8: =J8*utility_well+K8*utility_disease | O8: =J8+K8 | P8: =IF(A8>cycles-1,0,IF(AND(half_cycle=1,OR(A8=0,A8=cycles-1)),0.5,1)) | Q8: =1/(1+discount_rate)^A8 | R8: =M8*P8*Q8 | S8: =N8*P8*Q8 | T8: =O8*P8*Q8
A9: 5 | B9: =start_age+5 | C9: =incidence_rate*(1-rrr_intervention) | D9: =1-EXP(-C9*cycle_length) | E9: =1-EXP(-(gompertz_a*EXP(gompertz_b*MAX(0,B9-20)))*cycle_length) | F9: =1-EXP(-excess_mortality_rate*cycle_length) | G9: =IF((D9+E9)>1,D9/(D9+E9),D9) | H9: =IF((D9+E9)>1,E9/(D9+E9),E9) | I9: =MIN(1,E9+F9) | J9: =J8*(1-G8-H8) | K9: =J8*G8+K8*(1-I8) | L9: =L8+J8*H8+K8*I8 | M9: =J9*(cost_well_annual+cost_intervention_annual)+K9*cost_disease_annual | N9: =J9*utility_well+K9*utility_disease | O9: =J9+K9 | P9: =IF(A9>cycles-1,0,IF(AND(half_cycle=1,OR(A9=0,A9=cycles-1)),0.5,1)) | Q9: =1/(1+discount_rate)^A9 | R9: =M9*P9*Q9 | S9: =N9*P9*Q9 | T9: =O9*P9*Q9
A10: 6 | B10: =start_age+6 | C10: =incidence_rate*(1-rrr_intervention) | D10: =1-EXP(-C10*cycle_length) | E10: =1-EXP(-(gompertz_a*EXP(gompertz_b*MAX(0,B10-20)))*cycle_length) | F10: =1-EXP(-excess_mortality_rate*cycle_length) | G10: =IF((D10+E10)>1,D10/(D10+E10),D10) | H10: =IF((D10+E10)>1,E10/(D10+E10),E10) | I10: =MIN(1,E10+F10) | J10: =J9*(1-G9-H9) | K10: =J9*G9+K9*(1-I9) | L10: =L9+J9*H9+K9*I9 | M10: =J10*(cost_well_annual+cost_intervention_annual)+K10*cost_disease_annual | N10: =J10*utility_well+K10*utility_disease | O10: =J10+K10 | P10: =IF(A10>cycles-1,0,IF(AND(half_cycle=1,OR(A10=0,A10=cycles-1)),0.5,1)) | Q10: =1/(1+discount_rate)^A10 | R10: =M10*P10*Q10 | S10: =N10*P10*Q10 | T10: =O10*P10*Q10
A11: 7 | B11: =start_age+7 | C11: =incidence_rate*(1-rrr_intervention) | D11: =1-EXP(-C11*cycle_length) | E11: =1-EXP(-(gompertz_a*EXP(gompertz_b*MAX(0,B11-20)))*cycle_length) | F11: =1-EXP(-excess_mortality_rate*cycle_length) | G11: =IF((D11+E11)>1,D11/(D11+E11),D11) | H11: =IF((D11+E11)>1,E11/(D11+E11),E11) | I11: =MIN(1,E11+F11) | J11: =J10*(1-G10-H10) | K11: =J10*G10+K10*(1-I10) | L11: =L10+J10*H10+K10*I10 | M11: =J11*(cost_well_annual+cost_intervention_annual)+K11*cost_disease_annual | N11: =J11*utility_well+K11*utility_disease | O11: =J11+K11 | P11: =IF(A11>cycles-1,0,IF(AND(half_cycle=1,OR(A11=0,A11=cycles-1)),0.5,1)) | Q11: =1/(1+discount_rate)^A11 | R11: =M11*P11*Q11 | S11: =N11*P11*Q11 | T11: =O11*P11*Q11
A12: 8 | B12: =start_age+8 | C12: =incidence_rate*(1-rrr_intervention) | D12: =1-EXP(-C12*cycle_length) | E12: =1-EXP(-(gompertz_a*EXP(gompertz_b*MAX(0,B12-20)))*cycle_length) | F12: =1-EXP(-excess_mortality_rate*cycle_length) | G12: =IF((D12+E12)>1,D12/(D12+E12),D12) | H12: =IF((D12+E12)>1,E12/(D12+E12),E12) | I12: =MIN(1,E12+F12) | J12: =J11*(1-G11-H11) | K12: =J11*G11+K11*(1-I11) | L12: =L11+J11*H11+K11*I11 | M12: =J12*(cost_well_annual+cost_intervention_annual)+K12*cost_disease_annual | N12: =J12*utility_well+K12*utility_disease | O12: =J12+K12 | P12: =IF(A12>cycles-1,0,IF(AND(half_cycle=1,OR(A12=0,A12=cycles-1)),0.5,1)) | Q12: =1/(1+discount_rate)^A12 | R12: =M12*P12*Q12 | S12: =N12*P12*Q12 | T12: =O12*P12*Q12
A13: 9 | B13: =start_age+9 | C13: =incidence_rate*(1-rrr_intervention) | D13: =1-EXP(-C13*cycle_length) | E13: =1-EXP(-(gompertz_a*EXP(gompertz_b*MAX(0,B13-20)))*cycle_length) | F13: =1-EXP(-excess_mortality_rate*cycle_length) | G13: =IF((D13+E13)>1,D13/(D13+E13),D13) | H13: =IF((D13+E13)>1,E13/(D13+E13),E13) | I13: =MIN(1,E13+F13) | J13: =J12*(1-G12-H12) | K13: =J12*G12+K12*(1-I12) | L13: =L12+J12*H12+K12*I12 | M13: =J13*(cost_well_annual+cost_intervention_annual)+K13*cost_disease_annual | N13: =J13*utility_well+K13*utility_disease | O13: =J13+K13 | P13: =IF(A13>cycles-1,0,IF(AND(half_cycle=1,OR(A13=0,A13=cycles-1)),0.5,1)) | Q13: =1/(1+discount_rate)^A13 | R13: =M13*P13*Q13 | S13: =N13*P13*Q13 | T13: =O13*P13*Q13
A14: 10 | B14: =start_age+10 | C14: =incidence_rate*(1-rrr_intervention) | D14: =1-EXP(-C14*cycle_length) | E14: =1-EXP(-(gompertz_a*EXP(gompertz_b*MAX(0,B14-20)))*cycle_length) | F14: =1-EXP(-excess_mortality_rate*cycle_length) | G14: =IF((D14+E14)>1,D14/(D14+E14),D14) | H14: =IF((D14+E14)>1,E14/(D14+E14),E14) | I14: =MIN(1,E14+F14) | J14: =J13*(1-G13-H13) | K14: =J13*G13+K13*(1-I13) | L14: =L13+J13*H13+K13*I13 | M14: =J14*(cost_well_annual+cost_intervention_annual)+K14*cost_disease_annual | N14: =J14*utility_well+K14*utility_disease | O14: =J14+K14 | P14: =IF(A14>cycles-1,0,IF(AND(half_cycle=1,OR(A14=0,A14=cycles-1)),0.5,1)) | Q14: =1/(1+discount_rate)^A14 | R14: =M14*P14*Q14 | S14: =N14*P14*Q14 | T14: =O14*P14*Q14
A15: 11 | B15: =start_age+11 | C15: =incidence_rate*(1-rrr_intervention) | D15: =1-EXP(-C15*cycle_length) | E15: =1-EXP(-(gompertz_a*EXP(gompertz_b*MAX(0,B15-20)))*cycle_length) | F15: =1-EXP(-excess_mortality_rate*cycle_length) | G15: =IF((D15+E15)>1,D15/(D15+E15),D15) | H15: =IF((D15+E15)>1,E15/(D15+E15),E15) | I15: =MIN(1,E15+F15) | J15: =J14*(1-G14-H14) | K15: =J14*G14+K14*(1-I14) | L15: =L14+J14*H14+K14*I14 | M15: =J15*(cost_well_annual+cost_intervention_annual)+K15*cost_disease_annual | N15: =J15*utility_well+K15*utility_disease | O15: =J15+K15 | P15: =IF(A15>cycles-1,0,IF(AND(half_cycle=1,OR(A15=0,A15=cycles-1)),0.5,1)) | Q15: =1/(1+discount_rate)^A15 | R15: =M15*P15*Q15 | S15: =N15*P15*Q15 | T15: =O15*P15*Q15
A16: 12 | B16: =start_age+12 | C16: =incidence_rate*(1-rrr_intervention) | D16: =1-EXP(-C16*cycle_length) | E16: =1-EXP(-(gompertz_a*EXP(gompertz_b*MAX(0,B16-20)))*cycle_length) | F16: =1-EXP(-excess_mortality_rate*cycle_length) | G16: =IF((D16+E16)>1,D16/(D16+E16),D16) | H16: =IF((D16+E16)>1,E16/(D16+E16),E16) | I16: =MIN(1,E16+F16) | J16: =J15*(1-G15-H15) | K16: =J15*G15+K15*(1-I15) | L16: =L15+J15*H15+K15*I15 | M16: =J16*(cost_well_annual+cost_intervention_annual)+K16*cost_disease_annual | N16: =J16*utility_well+K16*utility_disease | O16: =J16+K16 | P16: =IF(A16>cycles-1,0,IF(AND(half_cycle=1,OR(A16=0,A16=cycles-1)),0.5,1)) | Q16: =1/(1+discount_rate)^A16 | R16: =M16*P16*Q16 | S16: =N16*P16*Q16 | T16: =O16*P16*Q16
A17: 13 | B17: =start_age+13 | C17: =incidence_rate*(1-rrr_intervention) | D17: =1-EXP(-C17*cycle_length) | E17: =1-EXP(-(gompertz_a*EXP(gompertz_b*MAX(0,B17-20)))*cycle_length) | F17: =1-EXP(-excess_mortality_rate*cycle_length) | G17: =IF((D17+E17)>1,D17/(D17+E17),D17) | H17: =IF((D17+E17)>1,E17/(D17+E17),E17) | I17: =MIN(1,E17+F17) | J17: =J16*(1-G16-H16) | K17: =J16*G16+K16*(1-I16) | L17: =L16+J16*H16+K16*I16 | M17: =J17*(cost_well_annual+cost_intervention_annual)+K17*cost_disease_annual | N17: =J17*utility_well+K17*utility_disease | O17: =J17+K17 | P17: =IF(A17>cycles-1,0,IF(AND(half_cycle=1,OR(A17=0,A17=cycles-1)),0.5,1)) | Q17: =1/(1+discount_rate)^A17 | R17: =M17*P17*Q17 | S17: =N17*P17*Q17 | T17: =O17*P17*Q17
A18: 14 | B18: =start_age+14 | C18: =incidence_rate*(1-rrr_intervention) | D18: =1-EXP(-C18*cycle_length) | E18: =1-EXP(-(gompertz_a*EXP(gompertz_b*MAX(0,B18-20)))*cycle_length) | F18: =1-EXP(-excess_mortality_rate*cycle_length) | G18: =IF((D18+E18)>1,D18/(D18+E18),D18) | H18: =IF((D18+E18)>1,E18/(D18+E18),E18) | I18: =MIN(1,E18+F18) | J18: =J17*(1-G17-H17) | K18: =J17*G17+K17*(1-I17) | L18: =L17+J17*H17+K17*I17 | M18: =J18*(cost_well_annual+cost_intervention_annual)+K18*cost_disease_annual | N18: =J18*utility_well+K18*utility_disease | O18: =J18+K18 | P18: =IF(A18>cycles-1,0,IF(AND(half_cycle=1,OR(A18=0,A18=cycles-1)),0.5,1)) | Q18: =1/(1+discount_rate)^A18 | R18: =M18*P18*Q18 | S18: =N18*P18*Q18 | T18: =O18*P18*Q18
A19: 15 | B19: =start_age+15 | C19: =incidence_rate*(1-rrr_intervention) | D19: =1-EXP(-C19*cycle_length) | E19: =1-EXP(-(gompertz_a*EXP(gompertz_b*MAX(0,B19-20)))*cycle_length) | F19: =1-EXP(-excess_mortality_rate*cycle_length) | G19: =IF((D19+E19)>1,D19/(D19+E19),D19) | H19: =IF((D19+E19)>1,E19/(D19+E19),E19) | I19: =MIN(1,E19+F19) | J19: =J18*(1-G18-H18) | K19: =J18*G18+K18*(1-I18) | L19: =L18+J18*H18+K18*I18 | M19: =J19*(cost_well_annual+cost_intervention_annual)+K19*cost_disease_annual | N19: =J19*utility_well+K19*utility_disease | O19: =J19+K19 | P19: =IF(A19>cycles-1,0,IF(AND(half_cycle=1,OR(A19=0,A19=cycles-1)),0.5,1)) | Q19: =1/(1+discount_rate)^A19 | R19: =M19*P19*Q19 | S19: =N19*P19*Q19 | T19: =O19*P19*Q19
A20: 16 | B20: =start_age+16 | C20: =incidence_rate*(1-rrr_intervention) | D20: =1-EXP(-C20*cycle_length) | E20: =1-EXP(-(gompertz_a*EXP(gompertz_b*MAX(0,B20-20)))*cycle_length) | F20: =1-EXP(-excess_mortality_rate*cycle_length) | G20: =IF((D20+E20)>1,D20/(D20+E20),D20) | H20: =IF((D20+E20)>1,E20/(D20+E20),E20) | I20: =MIN(1,E20+F20) | J20: =J19*(1-G19-H19) | K20: =J19*G19+K19*(1-I19) | L20: =L19+J19*H19+K19*I19 | M20: =J20*(cost_well_annual+cost_intervention_annual)+K20*cost_disease_annual | N20: =J20*utility_well+K20*utility_disease | O20: =J20+K20 | P20: =IF(A20>cycles-1,0,IF(AND(half_cycle=1,OR(A20=0,A20=cycles-1)),0.5,1)) | Q20: =1/(1+discount_rate)^A20 | R20: =M20*P20*Q20 | S20: =N20*P20*Q20 | T20: =O20*P20*Q20
A21: 17 | B21: =start_age+17 | C21: =incidence_rate*(1-rrr_intervention) | D21: =1-EXP(-C21*cycle_length) | E21: =1-EXP(-(gompertz_a*EXP(gompertz_b*MAX(0,B21-20)))*cycle_length) | F21: =1-EXP(-excess_mortality_rate*cycle_length) | G21: =IF((D21+E21)>1,D21/(D21+E21),D21) | H21: =IF((D21+E21)>1,E21/(D21+E21),E21) | I21: =MIN(1,E21+F21) | J21: =J20*(1-G20-H20) | K21: =J20*G20+K20*(1-I20) | L21: =L20+J20*H20+K20*I20 | M21: =J21*(cost_well_annual+cost_intervention_annual)+K21*cost_disease_annual | N21: =J21*utility_well+K21*utility_disease | O21: =J21+K21 | P21: =IF(A21>cycles-1,0,IF(AND(half_cycle=1,OR(A21=0,A21=cycles-1)),0.5,1)) | Q21: =1/(1+discount_rate)^A21 | R21: =M21*P21*Q21 | S21: =N21*P21*Q21 | T21: =O21*P21*Q21
A22: 18 | B22: =start_age+18 | C22: =incidence_rate*(1-rrr_intervention) | D22: =1-EXP(-C22*cycle_length) | E22: =1-EXP(-(gompertz_a*EXP(gompertz_b*MAX(0,B22-20)))*cycle_length) | F22: =1-EXP(-excess_mortality_rate*cycle_length) | G22: =IF((D22+E22)>1,D22/(D22+E22),D22) | H22: =IF((D22+E22)>1,E22/(D22+E22),E22) | I22: =MIN(1,E22+F22) | J22: =J21*(1-G21-H21) | K22: =J21*G21+K21*(1-I21) | L22: =L21+J21*H21+K21*I21 | M22: =J22*(cost_well_annual+cost_intervention_annual)+K22*cost_disease_annual | N22: =J22*utility_well+K22*utility_disease | O22: =J22+K22 | P22: =IF(A22>cycles-1,0,IF(AND(half_cycle=1,OR(A22=0,A22=cycles-1)),0.5,1)) | Q22: =1/(1+discount_rate)^A22 | R22: =M22*P22*Q22 | S22: =N22*P22*Q22 | T22: =O22*P22*Q22
A23: 19 | B23: =start_age+19 | C23: =incidence_rate*(1-rrr_intervention) | D23: =1-EXP(-C23*cycle_length) | E23: =1-EXP(-(gompertz_a*EXP(gompertz_b*MAX(0,B23-20)))*cycle_length) | F23: =1-EXP(-excess_mortality_rate*cycle_length) | G23: =IF((D23+E23)>1,D23/(D23+E23),D23) | H23: =IF((D23+E23)>1,E23/(D23+E23),E23) | I23: =MIN(1,E23+F23) | J23: =J22*(1-G22-H22) | K23: =J22*G22+K22*(1-I22) | L23: =L22+J22*H22+K22*I22 | M23: =J23*(cost_well_annual+cost_intervention_annual)+K23*cost_disease_annual | N23: =J23*utility_well+K23*utility_disease | O23: =J23+K23 | P23: =IF(A23>cycles-1,0,IF(AND(half_cycle=1,OR(A23=0,A23=cycles-1)),0.5,1)) | Q23: =1/(1+discount_rate)^A23 | R23: =M23*P23*Q23 | S23: =N23*P23*Q23 | T23: =O23*P23*Q23
A24: 20 | B24: =start_age+20 | C24: =incidence_rate*(1-rrr_intervention) | D24: =1-EXP(-C24*cycle_length) | E24: =1-EXP(-(gompertz_a*EXP(gompertz_b*MAX(0,B24-20)))*cycle_length) | F24: =1-EXP(-excess_mortality_rate*cycle_length) | G24: =IF((D24+E24)>1,D24/(D24+E24),D24) | H24: =IF((D24+E24)>1,E24/(D24+E24),E24) | I24: =MIN(1,E24+F24) | J24: =J23*(1-G23-H23) | K24: =J23*G23+K23*(1-I23) | L24: =L23+J23*H23+K23*I23 | M24: =J24*(cost_well_annual+cost_intervention_annual)+K24*cost_disease_annual | N24: =J24*utility_well+K24*utility_disease | O24: =J24+K24 | P24: =IF(A24>cycles-1,0,IF(AND(half_cycle=1,OR(A24=0,A24=cycles-1)),0.5,1)) | Q24: =1/(1+discount_rate)^A24 | R24: =M24*P24*Q24 | S24: =N24*P24*Q24 | T24: =O24*P24*Q24
A25: 21 | B25: =start_age+21 | C25: =incidence_rate*(1-rrr_intervention) | D25: =1-EXP(-C25*cycle_length) | E25: =1-EXP(-(gompertz_a*EXP(gompertz_b*MAX(0,B25-20)))*cycle_length) | F25: =1-EXP(-excess_mortality_rate*cycle_length) | G25: =IF((D25+E25)>1,D25/(D25+E25),D25) | H25: =IF((D25+E25)>1,E25/(D25+E25),E25) | I25: =MIN(1,E25+F25) | J25: =J24*(1-G24-H24) | K25: =J24*G24+K24*(1-I24) | L25: =L24+J24*H24+K24*I24 | M25: =J25*(cost_well_annual+cost_intervention_annual)+K25*cost_disease_annual | N25: =J25*utility_well+K25*utility_disease | O25: =J25+K25 | P25: =IF(A25>cycles-1,0,IF(AND(half_cycle=1,OR(A25=0,A25=cycles-1)),0.5,1)) | Q25: =1/(1+discount_rate)^A25 | R25: =M25*P25*Q25 | S25: =N25*P25*Q25 | T25: =O25*P25*Q25
A26: 22 | B26: =start_age+22 | C26: =incidence_rate*(1-rrr_intervention) | D26: =1-EXP(-C26*cycle_length) | E26: =1-EXP(-(gompertz_a*EXP(gompertz_b*MAX(0,B26-20)))*cycle_length) | F26: =1-EXP(-excess_mortality_rate*cycle_length) | G26: =IF((D26+E26)>1,D26/(D26+E26),D26) | H26: =IF((D26+E26)>1,E26/(D26+E26),E26) | I26: =MIN(1,E26+F26) | J26: =J25*(1-G25-H25) | K26: =J25*G25+K25*(1-I25) | L26: =L25+J25*H25+K25*I25 | M26: =J26*(cost_well_annual+cost_intervention_annual)+K26*cost_disease_annual | N26: =J26*utility_well+K26*utility_disease | O26: =J26+K26 | P26: =IF(A26>cycles-1,0,IF(AND(half_cycle=1,OR(A26=0,A26=cycles-1)),0.5,1)) | Q26: =1/(1+discount_rate)^A26 | R26: =M26*P26*Q26 | S26: =N26*P26*Q26 | T26: =O26*P26*Q26
A27: 23 | B27: =start_age+23 | C27: =incidence_rate*(1-rrr_intervention) | D27: =1-EXP(-C27*cycle_length) | E27: =1-EXP(-(gompertz_a*EXP(gompertz_b*MAX(0,B27-20)))*cycle_length) | F27: =1-EXP(-excess_mortality_rate*cycle_length) | G27: =IF((D27+E27)>1,D27/(D27+E27),D27) | H27: =IF((D27+E27)>1,E27/(D27+E27),E27) | I27: =MIN(1,E27+F27) | J27: =J26*(1-G26-H26) | K27: =J26*G26+K26*(1-I26) | L27: =L26+J26*H26+K26*I26 | M27: =J27*(cost_well_annual+cost_intervention_annual)+K27*cost_disease_annual | N27: =J27*utility_well+K27*utility_disease | O27: =J27+K27 | P27: =IF(A27>cycles-1,0,IF(AND(half_cycle=1,OR(A27=0,A27=cycles-1)),0.5,1)) | Q27: =1/(1+discount_rate)^A27 | R27: =M27*P27*Q27 | S27: =N27*P27*Q27 | T27: =O27*P27*Q27
A28: 24 | B28: =start_age+24 | C28: =incidence_rate*(1-rrr_intervention) | D28: =1-EXP(-C28*cycle_length) | E28: =1-EXP(-(gompertz_a*EXP(gompertz_b*MAX(0,B28-20)))*cycle_length) | F28: =1-EXP(-excess_mortality_rate*cycle_length) | G28: =IF((D28+E28)>1,D28/(D28+E28),D28) | H28: =IF((D28+E28)>1,E28/(D28+E28),E28) | I28: =MIN(1,E28+F28) | J28: =J27*(1-G27-H27) | K28: =J27*G27+K27*(1-I27) | L28: =L27+J27*H27+K27*I27 | M28: =J28*(cost_well_annual+cost_intervention_annual)+K28*cost_disease_annual | N28: =J28*utility_well+K28*utility_disease | O28: =J28+K28 | P28: =IF(A28>cycles-1,0,IF(AND(half_cycle=1,OR(A28=0,A28=cycles-1)),0.5,1)) | Q28: =1/(1+discount_rate)^A28 | R28: =M28*P28*Q28 | S28: =N28*P28*Q28 | T28: =O28*P28*Q28
A29: 25 | B29: =start_age+25 | C29: =incidence_rate*(1-rrr_intervention) | D29: =1-EXP(-C29*cycle_length) | E29: =1-EXP(-(gompertz_a*EXP(gompertz_b*MAX(0,B29-20)))*cycle_length) | F29: =1-EXP(-excess_mortality_rate*cycle_length) | G29: =IF((D29+E29)>1,D29/(D29+E29),D29) | H29: =IF((D29+E29)>1,E29/(D29+E29),E29) | I29: =MIN(1,E29+F29) | J29: =J28*(1-G28-H28) | K29: =J28*G28+K28*(1-I28) | L29: =L28+J28*H28+K28*I28 | M29: =J29*(cost_well_annual+cost_intervention_annual)+K29*cost_disease_annual | N29: =J29*utility_well+K29*utility_disease | O29: =J29+K29 | P29: =IF(A29>cycles-1,0,IF(AND(half_cycle=1,OR(A29=0,A29=cycles-1)),0.5,1)) | Q29: =1/(1+discount_rate)^A29 | R29: =M29*P29*Q29 | S29: =N29*P29*Q29 | T29: =O29*P29*Q29
A30: 26 | B30: =start_age+26 | C30: =incidence_rate*(1-rrr_intervention) | D30: =1-EXP(-C30*cycle_length) | E30: =1-EXP(-(gompertz_a*EXP(gompertz_b*MAX(0,B30-20)))*cycle_length) | F30: =1-EXP(-excess_mortality_rate*cycle_length) | G30: =IF((D30+E30)>1,D30/(D30+E30),D30) | H30: =IF((D30+E30)>1,E30/(D30+E30),E30) | I30: =MIN(1,E30+F30) | J30: =J29*(1-G29-H29) | K30: =J29*G29+K29*(1-I29) | L30: =L29+J29*H29+K29*I29 | M30: =J30*(cost_well_annual+cost_intervention_annual)+K30*cost_disease_annual | N30: =J30*utility_well+K30*utility_disease | O30: =J30+K30 | P30: =IF(A30>cycles-1,0,IF(AND(half_cycle=1,OR(A30=0,A30=cycles-1)),0.5,1)) | Q30: =1/(1+discount_rate)^A30 | R30: =M30*P30*Q30 | S30: =N30*P30*Q30 | T30: =O30*P30*Q30
A31: 27 | B31: =start_age+27 | C31: =incidence_rate*(1-rrr_intervention) | D31: =1-EXP(-C31*cycle_length) | E31: =1-EXP(-(gompertz_a*EXP(gompertz_b*MAX(0,B31-20)))*cycle_length) | F31: =1-EXP(-excess_mortality_rate*cycle_length) | G31: =IF((D31+E31)>1,D31/(D31+E31),D31) | H31: =IF((D31+E31)>1,E31/(D31+E31),E31) | I31: =MIN(1,E31+F31) | J31: =J30*(1-G30-H30) | K31: =J30*G30+K30*(1-I30) | L31: =L30+J30*H30+K30*I30 | M31: =J31*(cost_well_annual+cost_intervention_annual)+K31*cost_disease_annual | N31: =J31*utility_well+K31*utility_disease | O31: =J31+K31 | P31: =IF(A31>cycles-1,0,IF(AND(half_cycle=1,OR(A31=0,A31=cycles-1)),0.5,1)) | Q31: =1/(1+discount_rate)^A31 | R31: =M31*P31*Q31 | S31: =N31*P31*Q31 | T31: =O31*P31*Q31
A32: 28 | B32: =start_age+28 | C32: =incidence_rate*(1-rrr_intervention) | D32: =1-EXP(-C32*cycle_length) | E32: =1-EXP(-(gompertz_a*EXP(gompertz_b*MAX(0,B32-20)))*cycle_length) | F32: =1-EXP(-excess_mortality_rate*cycle_length) | G32: =IF((D32+E32)>1,D32/(D32+E32),D32) | H32: =IF((D32+E32)>1,E32/(D32+E32),E32) | I32: =MIN(1,E32+F32) | J32: =J31*(1-G31-H31) | K32: =J31*G31+K31*(1-I31) | L32: =L31+J31*H31+K31*I31 | M32: =J32*(cost_well_annual+cost_intervention_annual)+K32*cost_disease_annual | N32: =J32*utility_well+K32*utility_disease | O32: =J32+K32 | P32: =IF(A32>cycles-1,0,IF(AND(half_cycle=1,OR(A32=0,A32=cycles-1)),0.5,1)) | Q32: =1/(1+discount_rate)^A32 | R32: =M32*P32*Q32 | S32: =N32*P32*Q32 | T32: =O32*P32*Q32
A33: 29 | B33: =start_age+29 | C33: =incidence_rate*(1-rrr_intervention) | D33: =1-EXP(-C33*cycle_length) | E33: =1-EXP(-(gompertz_a*EXP(gompertz_b*MAX(0,B33-20)))*cycle_length) | F33: =1-EXP(-excess_mortality_rate*cycle_length) | G33: =IF((D33+E33)>1,D33/(D33+E33),D33) | H33: =IF((D33+E33)>1,E33/(D33+E33),E33) | I33: =MIN(1,E33+F33) | J33: =J32*(1-G32-H32) | K33: =J32*G32+K32*(1-I32) | L33: =L32+J32*H32+K32*I32 | M33: =J33*(cost_well_annual+cost_intervention_annual)+K33*cost_disease_annual | N33: =J33*utility_well+K33*utility_disease | O33: =J33+K33 | P33: =IF(A33>cycles-1,0,IF(AND(half_cycle=1,OR(A33=0,A33=cycles-1)),0.5,1)) | Q33: =1/(1+discount_rate)^A33 | R33: =M33*P33*Q33 | S33: =N33*P33*Q33 | T33: =O33*P33*Q33
A34: 30 | B34: =start_age+30 | C34: =incidence_rate*(1-rrr_intervention) | D34: =1-EXP(-C34*cycle_length) | E34: =1-EXP(-(gompertz_a*EXP(gompertz_b*MAX(0,B34-20)))*cycle_length) | F34: =1-EXP(-excess_mortality_rate*cycle_length) | G34: =IF((D34+E34)>1,D34/(D34+E34),D34) | H34: =IF((D34+E34)>1,E34/(D34+E34),E34) | I34: =MIN(1,E34+F34) | J34: =J33*(1-G33-H33) | K34: =J33*G33+K33*(1-I33) | L34: =L33+J33*H33+K33*I33 | M34: =J34*(cost_well_annual+cost_intervention_annual)+K34*cost_disease_annual | N34: =J34*utility_well+K34*utility_disease | O34: =J34+K34 | P34: =IF(A34>cycles-1,0,IF(AND(half_cycle=1,OR(A34=0,A34=cycles-1)),0.5,1)) | Q34: =1/(1+discount_rate)^A34 | R34: =M34*P34*Q34 | S34: =N34*P34*Q34 | T34: =O34*P34*Q34
A35: 31 | B35: =start_age+31 | C35: =incidence_rate*(1-rrr_intervention) | D35: =1-EXP(-C35*cycle_length) | E35: =1-EXP(-(gompertz_a*EXP(gompertz_b*MAX(0,B35-20)))*cycle_length) | F35: =1-EXP(-excess_mortality_rate*cycle_length) | G35: =IF((D35+E35)>1,D35/(D35+E35),D35) | H35: =IF((D35+E35)>1,E35/(D35+E35),E35) | I35: =MIN(1,E35+F35) | J35: =J34*(1-G34-H34) | K35: =J34*G34+K34*(1-I34) | L35: =L34+J34*H34+K34*I34 | M35: =J35*(cost_well_annual+cost_intervention_annual)+K35*cost_disease_annual | N35: =J35*utility_well+K35*utility_disease | O35: =J35+K35 | P35: =IF(A35>cycles-1,0,IF(AND(half_cycle=1,OR(A35=0,A35=cycles-1)),0.5,1)) | Q35: =1/(1+discount_rate)^A35 | R35: =M35*P35*Q35 | S35: =N35*P35*Q35 | T35: =O35*P35*Q35
A36: 32 | B36: =start_age+32 | C36: =incidence_rate*(1-rrr_intervention) | D36: =1-EXP(-C36*cycle_length) | E36: =1-EXP(-(gompertz_a*EXP(gompertz_b*MAX(0,B36-20)))*cycle_length) | F36: =1-EXP(-excess_mortality_rate*cycle_length) | G36: =IF((D36+E36)>1,D36/(D36+E36),D36) | H36: =IF((D36+E36)>1,E36/(D36+E36),E36) | I36: =MIN(1,E36+F36) | J36: =J35*(1-G35-H35) | K36: =J35*G35+K35*(1-I35) | L36: =L35+J35*H35+K35*I35 | M36: =J36*(cost_well_annual+cost_intervention_annual)+K36*cost_disease_annual | N36: =J36*utility_well+K36*utility_disease | O36: =J36+K36 | P36: =IF(A36>cycles-1,0,IF(AND(half_cycle=1,OR(A36=0,A36=cycles-1)),0.5,1)) | Q36: =1/(1+discount_rate)^A36 | R36: =M36*P36*Q36 | S36: =N36*P36*Q36 | T36: =O36*P36*Q36
A37: 33 | B37: =start_age+33 | C37: =incidence_rate*(1-rrr_intervention) | D37: =1-EXP(-C37*cycle_length) | E37: =1-EXP(-(gompertz_a*EXP(gompertz_b*MAX(0,B37-20)))*cycle_length) | F37: =1-EXP(-excess_mortality_rate*cycle_length) | G37: =IF((D37+E37)>1,D37/(D37+E37),D37) | H37: =IF((D37+E37)>1,E37/(D37+E37),E37) | I37: =MIN(1,E37+F37) | J37: =J36*(1-G36-H36) | K37: =J36*G36+K36*(1-I36) | L37: =L36+J36*H36+K36*I36 | M37: =J37*(cost_well_annual+cost_intervention_annual)+K37*cost_disease_annual | N37: =J37*utility_well+K37*utility_disease | O37: =J37+K37 | P37: =IF(A37>cycles-1,0,IF(AND(half_cycle=1,OR(A37=0,A37=cycles-1)),0.5,1)) | Q37: =1/(1+discount_rate)^A37 | R37: =M37*P37*Q37 | S37: =N37*P37*Q37 | T37: =O37*P37*Q37
A38: 34 | B38: =start_age+34 | C38: =incidence_rate*(1-rrr_intervention) | D38: =1-EXP(-C38*cycle_length) | E38: =1-EXP(-(gompertz_a*EXP(gompertz_b*MAX(0,B38-20)))*cycle_length) | F38: =1-EXP(-excess_mortality_rate*cycle_length) | G38: =IF((D38+E38)>1,D38/(D38+E38),D38) | H38: =IF((D38+E38)>1,E38/(D38+E38),E38) | I38: =MIN(1,E38+F38) | J38: =J37*(1-G37-H37) | K38: =J37*G37+K37*(1-I37) | L38: =L37+J37*H37+K37*I37 | M38: =J38*(cost_well_annual+cost_intervention_annual)+K38*cost_disease_annual | N38: =J38*utility_well+K38*utility_disease | O38: =J38+K38 | P38: =IF(A38>cycles-1,0,IF(AND(half_cycle=1,OR(A38=0,A38=cycles-1)),0.5,1)) | Q38: =1/(1+discount_rate)^A38 | R38: =M38*P38*Q38 | S38: =N38*P38*Q38 | T38: =O38*P38*Q38
A39: 35 | B39: =start_age+35 | C39: =incidence_rate*(1-rrr_intervention) | D39: =1-EXP(-C39*cycle_length) | E39: =1-EXP(-(gompertz_a*EXP(gompertz_b*MAX(0,B39-20)))*cycle_length) | F39: =1-EXP(-excess_mortality_rate*cycle_length) | G39: =IF((D39+E39)>1,D39/(D39+E39),D39) | H39: =IF((D39+E39)>1,E39/(D39+E39),E39) | I39: =MIN(1,E39+F39) | J39: =J38*(1-G38-H38) | K39: =J38*G38+K38*(1-I38) | L39: =L38+J38*H38+K38*I38 | M39: =J39*(cost_well_annual+cost_intervention_annual)+K39*cost_disease_annual | N39: =J39*utility_well+K39*utility_disease | O39: =J39+K39 | P39: =IF(A39>cycles-1,0,IF(AND(half_cycle=1,OR(A39=0,A39=cycles-1)),0.5,1)) | Q39: =1/(1+discount_rate)^A39 | R39: =M39*P39*Q39 | S39: =N39*P39*Q39 | T39: =O39*P39*Q39
A40: 36 | B40: =start_age+36 | C40: =incidence_rate*(1-rrr_intervention) | D40: =1-EXP(-C40*cycle_length) | E40: =1-EXP(-(gompertz_a*EXP(gompertz_b*MAX(0,B40-20)))*cycle_length) | F40: =1-EXP(-excess_mortality_rate*cycle_length) | G40: =IF((D40+E40)>1,D40/(D40+E40),D40) | H40: =IF((D40+E40)>1,E40/(D40+E40),E40) | I40: =MIN(1,E40+F40) | J40: =J39*(1-G39-H39) | K40: =J39*G39+K39*(1-I39) | L40: =L39+J39*H39+K39*I39 | M40: =J40*(cost_well_annual+cost_intervention_annual)+K40*cost_disease_annual | N40: =J40*utility_well+K40*utility_disease | O40: =J40+K40 | P40: =IF(A40>cycles-1,0,IF(AND(half_cycle=1,OR(A40=0,A40=cycles-1)),0.5,1)) | Q40: =1/(1+discount_rate)^A40 | R40: =M40*P40*Q40 | S40: =N40*P40*Q40 | T40: =O40*P40*Q40
A41: 37 | B41: =start_age+37 | C41: =incidence_rate*(1-rrr_intervention) | D41: =1-EXP(-C41*cycle_length) | E41: =1-EXP(-(gompertz_a*EXP(gompertz_b*MAX(0,B41-20)))*cycle_length) | F41: =1-EXP(-excess_mortality_rate*cycle_length) | G41: =IF((D41+E41)>1,D41/(D41+E41),D41) | H41: =IF((D41+E41)>1,E41/(D41+E41),E41) | I41: =MIN(1,E41+F41) | J41: =J40*(1-G40-H40) | K41: =J40*G40+K40*(1-I40) | L41: =L40+J40*H40+K40*I40 | M41: =J41*(cost_well_annual+cost_intervention_annual)+K41*cost_disease_annual | N41: =J41*utility_well+K41*utility_disease | O41: =J41+K41 | P41: =IF(A41>cycles-1,0,IF(AND(half_cycle=1,OR(A41=0,A41=cycles-1)),0.5,1)) | Q41: =1/(1+discount_rate)^A41 | R41: =M41*P41*Q41 | S41: =N41*P41*Q41 | T41: =O41*P41*Q41
...
